Workbook

Sheet Assumptions
A1: WAKASA LABS — FINANCIAL ASSUMPTIONS
A2: Exchange Rate (1 USD = Ksh) | B2: 130 | C2: ← Update if rate changes
A4: SECTION A — ONE-TIME STARTUP COSTS
A5: Item | B5: Amount (Ksh) | C5: Notes / Source
A6: Company Registration (Kenya) | B6: 20000 | C6: BRS/eCitizen — est. Ksh 20,000
A7: School Outreach (fares + miscellaneous) | B7: 290000 | C7: Transport, printing, communications — Month 1
A8: Domain Name (.com + privacy, $86/yr) | B8: =ROUND(86*B2,0) -> 11180 | C8: Namecheap or similar. $78 domain + $8 privacy/yr
A9: Model Training & Fine-Tuning ($1,000/yr) | B9: =ROUND(1000*B2,0) -> 130000 | C9: Annual cost, paid upfront Year 1
A10: TOTAL ONE-TIME COSTS | B10: =SUM(B6:B9) -> 451180 | C10: Paid in Month 1 only
A12: SECTION B — MONTHLY FIXED COSTS (recurring every month)
A13: Item | B13: Amount (Ksh) | C13: Notes / Source
A14: Vercel Deployment ($25/month) | B14: =ROUND(25*B2,0) -> 3250 | C14: Frontend + serverless hosting
A15: Supabase ($25/month) | B15: =ROUND(25*B2,0) -> 3250 | C15: Database + auth + storage
A16: Gemini API (base subscription) | B16: 900 | C16: Google Gemini monthly plan — Ksh 900
A17: Electricity ($40/month) | B17: =ROUND(40*B2,0) -> 5200 | C17: Home/office power for servers & dev equipment
A18: TOTAL MONTHLY FIXED | B18: =SUM(B14:B17) -> 12600 | C18: Does not include variable API or people costs
A20: SECTION C — VARIABLE COST (scales with usage)
A21: Item | B21: Amount (Ksh) | C21: Notes / Source
A22: API Request Cost Rate ($ per 1,000 requests) | B22: 5 | C22: Source: pricing stated. $5 per 1,000 requests.
A23: Exam Requests per Month (pilot) | B23: 5000 | C23: ← Your pilot estimate. Change this to model scenarios.
A24: Monthly API Cost (calculated) | B24: =ROUND((B23/1000)*B22*B2,0) -> 3250 | C24: Grows proportionally with exam volume
A25: TOTAL MONTHLY VARIABLE | B25: =B24 -> 3250 | C25: Grows as request volume grows
A27: SECTION D — PEOPLE COSTS
A28: Item | B28: Amount (Ksh) | C28: Notes / Source
A29: Founder 1 Monthly Salary | B29: 0 | C29: Set to 0 for now — adjust when funded
A30: Founder 2 Monthly Salary | B30: 0 | C30: Set to 0 for now — adjust when funded
A31: DevOps Engineer (contract — monthly) | B31: 25000 | C31: Ksh 20,000–30,000 range. Using Ksh 25,000 midpoint
A32: DevOps Contract Duration (months) | B32: 2 | C32: Estimated 2 months to complete deployment setup
A33: Total DevOps One-Time Cost | B33: =B31*B32 -> 50000 | C33: One-time contract, not recurring
A34: TOTAL MONTHLY PEOPLE (recurring) | B34: =B29+B30 -> 0 | C34: Monthly founder salaries only (DevOps is one-time)
A36: SECTION E — SUMMARY TOTALS
A37: Item | B37: Amount (Ksh) | C37: Notes / Source
A38: Total One-Time Costs (registration, domain, training) | B38: =B10 -> 451180 | C38: From Section A
A39: Total DevOps One-Time Cost | B39: =B33 -> 50000 | C39: From Section D — contract labour
A40: ALL ONE-TIME COSTS COMBINED | B40: =B38+B39 -> 501180
A42: Total Monthly Fixed (infrastructure) | B42: =B18 -> 12600 | C42: From Section B
A43: Total Monthly Variable (API at pilot volume) | B43: =B25 -> 3250 | C43: From Section C — scales with requests
A44: Total Monthly People (founder salaries) | B44: =B34 -> 0 | C44: From Section D
A45: TOTAL MONTHLY BURN RATE | B45: =B42+B43+B44 -> 15850
A47: SECTION F — AI MODEL COSTS (MVP Phase)
...

Sheet Runway & Funding
A1: WAKASA LABS — RUNWAY & FUNDING REQUIREMENT
A3: 6-MONTH RUNWAY BREAKDOWN
A4: Cost Item | B4: Calculation | C4: Amount (Ksh) | D4: Monthly? | E4: Notes
A5: One-time startup costs | B5: =Assumptions!B40 -> 501180 | C5: =ROUND(B5/Assumptions!B2,0) -> 3855 | D5: One-time | E5: Registration, domain, training, DevOps
A6: Monthly fixed (infra) | B6: =Assumptions!B18*6 -> 75600 | C6: =ROUND(B6/Assumptions!B2,0) -> 582 | D6: Yes | E6: Ksh fixed × 6 months
A7: Monthly variable (API) | B7: =Assumptions!B25*6 -> 19500 | C7: =ROUND(B7/Assumptions!B2,0) -> 150 | D7: Yes | E7: At 1,300 requests/mo × 6 months
A8: Monthly people costs | B8: =Assumptions!B34*6 -> 0 | C8: =ROUND(B8/Assumptions!B2,0) -> 0 | D8: Yes | E8: Founder salaries × 6 months
A9: SUBTOTAL — 6-Month Operational | B9: =B5+B6+B7+B8 -> 596280 | C9: =ROUND(B9/Assumptions!B2,0) -> 4587 | D9: One-time
A10: Safety Buffer (20%) | B10: =B9*0.2 -> 119256 | C10: =ROUND(B10/Assumptions!B2,0) -> 917 | D10: One-time | E10: Standard investor buffer — unexpected costs
A11: ★ TOTAL 6-MONTH FUNDING NEEDED | B11: =B9+B10 -> 715536 | C11: =ROUND(B11/Assumptions!B2,0) -> 5504 | D11: One-time | E11: Amount to request from investor
A16: 12-MONTH RUNWAY BREAKDOWN
A17: Cost Item | B17: Calculation | C17: Amount (Ksh) | D17: Monthly? | E17: Notes
A18: One-time startup costs | B18: =Assumptions!B40 -> 501180 | C18: =ROUND(B18/Assumptions!B2,0) -> 3855 | D18: One-time | E18: Registration, domain, training, DevOps
A19: Monthly fixed (infra) | B19: =Assumptions!B18*12 -> 151200 | C19: =ROUND(B19/Assumptions!B2,0) -> 1163 | D19: Yes | E19: Ksh fixed × 12 months
A20: Monthly variable (API) | B20: =Assumptions!B25*12 -> 39000 | C20: =ROUND(B20/Assumptions!B2,0) -> 300 | D20: Yes | E20: At 1,300 requests/mo × 12 months
A21: Monthly people costs | B21: =Assumptions!B34*12 -> 0 | C21: =ROUND(B21/Assumptions!B2,0) -> 0 | D21: Yes | E21: Founder salaries × 12 months
A22: Model cloud hosting (Months 7–12) | B22: =Assumptions!B85*6 -> 0 | C22: =ROUND(B22/Assumptions!B2,0) -> 0 | D22: Yes | E22: GPU cloud — own model serving from Month 7 onward
A23: SUBTOTAL — 12-Month Operational | B23: =B18+B19+B20+B21+B22 -> 691380 | C23: =ROUND(B23/Assumptions!B2,0) -> 5318 | D23: One-time
A24: Safety Buffer (20%) | B24: =B23*0.2 -> 138276 | C24: =ROUND(B24/Assumptions!B2,0) -> 1064 | D24: One-time | E24: Standard investor buffer — unexpected costs
A25: ★ TOTAL 12-MONTH FUNDING NEEDED | B25: =B23+B24 -> 829656 | C25: =ROUND(B25/Assumptions!B2,0) -> 6382 | D25: One-time | E25: Amount to request from investor
A31: INVESTOR SUMMARY — WHAT TO ASK FOR
A32: Scenario | B32: Ksh Amount | C32: USD Amount | D32: Runway | E32: Recommendation
A33: 6-Month Runway | B33: =B11 -> 715536 | C33: =ROUND(B11/Assumptions!B2,0) -> 5504 | D33: 6 months | E33: Minimum viable — tight
A34: 12-Month Runway | B34: =B25 -> 829656 | C34: =ROUND(B25/Assumptions!B2,0) -> 6382 | D34: 12 months | E34: ★ RECOMMENDED gives time to reach revenue
A36: AI MODEL COSTS — MVP PHASE SUMMARY
A37: Scenario | B37: Monthly Cost (Ksh) | C37: Annual Cost (Ksh) | D37: Notes
A38: Pilot: 500 papers/mo — Claude Batch | B38: =ROUND((0.0222*500*130),0) -> 1443 | C38: =ROUND(B38/Assumptions!B2,0) -> 11 | D38: Claude Sonnet 4.6 batch pricing
A39: Growth: 2,000 papers/mo — Claude Batch | B39: =ROUND((0.0222*2000*130),0) -> 5772 | C39: =B38*12 -> 17316 | D39: Exceeds infra cost — plan model transition
A40: Scale: 5,000 papers/mo — Own Model | B40: =ROUND(Assumptions!B70*Assumptions!B2,0) -> 298220 | C40: =B39*12 -> 69264 | D40: Flat GPU hosting. Crossover point reached
A41: Fine-Tune Investment (one-time, Ksh) | B41: =ROUND(170*130,0) -> 22100 | C41: One-time | D41: Covers all 3 models. Recur every 6 months

Sheet Break-Even Pricing
A1: WAKASA LABS — BREAK-EVEN PRICING CALCULATOR
A2: Minimum price per exam to cover all monthly costs at each volume level
G3: Claude Batch/Paper ($) | H3: Gemini Flash/Paper ($) | I3: Own Model/Paper ($) hosting amortised
A4: Requests/Month | B4: Monthly Infra (Ksh) | C4: Monthly API Cost (Ksh) | D4: Total Monthly Burn (Ksh) | E4: Min Price/Exam (Ksh) | F4: Min Price/Exam ($) | G4: 0.0222 | H4: 0.0043 | I4: 0.1154
A5: 1300 | B5: =Assumptions!B18 -> 12600 | C5: =ROUND((A5/1000)*Assumptions!B22*Assumptions!B2,0) -> 845 | D5: =B5+C5 -> 13445 | E5: =ROUNDUP(D5/A5,0) -> 11 | F5: =ROUND(E5/Assumptions!B2,2) -> 0.08 | G5: 0.0222 | H5: 0.0043 | I5: =ROUND(Assumptions!B84/A5,4) -> 0
A6: 2500 | B6: =Assumptions!B18 -> 12600 | C6: =ROUND((A6/1000)*Assumptions!B22*Assumptions!B2,0) -> 1625 | D6: =B6+C6 -> 14225 | E6: =ROUNDUP(D6/A6,0) -> 6 | F6: =ROUND(E6/Assumptions!B2,2) -> 0.05 | G6: 0.0222 | H6: 0.0043 | I6: =ROUND(Assumptions!B84/A6,4) -> 0
A7: 5000 | B7: =Assumptions!B18 -> 12600 | C7: =ROUND((A7/1000)*Assumptions!B22*Assumptions!B2,0) -> 3250 | D7: =B7+C7 -> 15850 | E7: =ROUNDUP(D7/A7,0) -> 4 | F7: =ROUND(E7/Assumptions!B2,2) -> 0.03 | G7: 0.0222 | H7: 0.0043 | I7: =ROUND(Assumptions!B84/A7,4) -> 0
A8: 10000 | B8: =Assumptions!B18 -> 12600 | C8: =ROUND((A8/1000)*Assumptions!B22*Assumptions!B2,0) -> 6500 | D8: =B8+C8 -> 19100 | E8: =ROUNDUP(D8/A8,0) -> 2 | F8: =ROUND(E8/Assumptions!B2,2) -> 0.02 | G8: 0.0222 | H8: 0.0043 | I8: =ROUND(Assumptions!B84/A8,4) -> 0
A9: 25000 | B9: =Assumptions!B18 -> 12600 | C9: =ROUND((A9/1000)*Assumptions!B22*Assumptions!B2,0) -> 16250 | D9: =B9+C9 -> 28850 | E9: =ROUNDUP(D9/A9,0) -> 2 | F9: =ROUND(E9/Assumptions!B2,2) -> 0.02 | G9: 0.0222 | H9: 0.0043 | I9: =ROUND(Assumptions!B84/A9,4) -> 0
A10: 50000 | B10: =Assumptions!B18 -> 12600 | C10: =ROUND((A10/1000)*Assumptions!B22*Assumptions!B2,0) -> 32500 | D10: =B10+C10 -> 45100 | E10: =ROUNDUP(D10/A10,0) -> 1 | F10: =ROUND(E10/Assumptions!B2,2) -> 0.01 | G10: 0.0222 | H10: 0.0043 | I10: =ROUND(Assumptions!B84/A10,4) -> 0
A11: 75000 | B11: =Assumptions!B18 -> 12600 | C11: =ROUND((A11/1000)*Assumptions!B22*Assumptions!B2,0) -> 48750 | D11: =B11+C11 -> 61350 | E11: =ROUNDUP(D11/A11,0) -> 1 | F11: =ROUND(E11/Assumptions!B2,2) -> 0.01 | G11: 0.0222 | H11: 0.0043 | I11: =ROUND(Assumptions!B84/A11,4) -> 0
A12: 100000 | B12: =Assumptions!B18 -> 12600 | C12: =ROUND((A12/1000)*Assumptions!B22*Assumptions!B2,0) -> 65000 | D12: =B12+C12 -> 77600 | E12: =ROUNDUP(D12/A12,0) -> 1 | F12: =ROUND(E12/Assumptions!B2,2) -> 0.01 | I12: =ROUND(Assumptions!B84/A12,4) -> 0
G13: Claude Sonnet 4.6 batch: $1.50/$7.50 per 1M tokens (in/out). Own Model: 1x H100 PCIe ($2.79/hr) + 1x RTX 4090 ($0.39/hr) on RunPod on-demand, amortized per paper volume. Source: runpod.io, Mar 2026.
A14: ★ Highlighted row = your pilot volume (1,300 requests). Founder salaries excluded from break-even — add when set.

Sheet Month-by-Month (Yr 1)
A1: WAKASA LABS — MONTH-BY-MONTH COST TRACKER (YEAR 1)
A2: Cost Item | B2: Month 1 | C2: Month 2 | D2: Month 3 | E2: Month 4 | F2: Month 5 | G2: Month 6 | H2: Month 7 | I2: Month 8 | J2: Month 9 | K2: Month 10 | L2: Month 11 | M2: Month 12
A3: Company Registration | B3: 20000 | C3: 0 | D3: 0 | E3: 0 | F3: 0 | G3: 0 | H3: 0 | I3: 0 | J3: 0 | K3: 0 | L3: 0 | M3: 0
A4: School Outreach | B4: 300000 | C4: 0 | D4: 0 | E4: 0 | F4: 0 | G4: 0 | H4: 0 | I4: 0 | J4: 0 | K4: 0 | L4: 0 | M4: 0
A5: Domain (annual, paid M1) | B5: 22230 | C5: 0 | D5: 0 | E5: 0 | F5: 0 | G5: 0 | H5: 0 | I5: 0 | J5: 0 | K5: 0 | L5: 0 | M5: 0
A6: Model Training (annual M1) | B6: =ROUND(1000*Assumptions!B2,0) -> 130000 | C6: 0 | D6: 0 | E6: 0 | F6: 0 | G6: 0 | H6: 0 | I6: 0 | J6: 0 | K6: 0 | L6: 0 | M6: 0
A7: DevOps Contract (2 months) | B7: =Assumptions!B31 -> 25000 | C7: =Assumptions!B31 -> 25000 | D7: 0 | E7: 0 | F7: 0 | G7: 0 | H7: 0 | I7: 0 | J7: 0 | K7: 0 | L7: 0 | M7: 0
A8: Vercel ($25/mo) | B8: =ROUND(25*Assumptions!B2,0) -> 3250 | C8: =ROUND(25*Assumptions!B2,0) -> 3250 | D8: =ROUND(25*Assumptions!B2,0) -> 3250 | E8: =ROUND(25*Assumptions!B2,0) -> 3250 | F8: =ROUND(25*Assumptions!B2,0) -> 3250 | G8: =ROUND(25*Assumptions!B2,0) -> 3250 | H8: =ROUND(25*Assumptions!B2,0) -> 3250 | I8: =ROUND(25*Assumptions!B2,0) -> 3250 | J8: =ROUND(25*Assumptions!B2,0) -> 3250 | K8: =ROUND(25*Assumptions!B2,0) -> 3250 | L8: =ROUND(25*Assumptions!B2,0) -> 3250 | M8: =ROUND(25*Assumptions!B2,0) -> 3250
A9: Supabase ($25/mo) | B9: =ROUND(25*Assumptions!B2,0) -> 3250 | C9: =ROUND(25*Assumptions!B2,0) -> 3250 | D9: =ROUND(25*Assumptions!B2,0) -> 3250 | E9: =ROUND(25*Assumptions!B2,0) -> 3250 | F9: =ROUND(25*Assumptions!B2,0) -> 3250 | G9: =ROUND(25*Assumptions!B2,0) -> 3250 | H9: =ROUND(25*Assumptions!B2,0) -> 3250 | I9: =ROUND(25*Assumptions!B2,0) -> 3250 | J9: =ROUND(25*Assumptions!B2,0) -> 3250 | K9: =ROUND(25*Assumptions!B2,0) -> 3250 | L9: =ROUND(25*Assumptions!B2,0) -> 3250 | M9: =ROUND(25*Assumptions!B2,0) -> 3250
A10: Gemini API | B10: 900 | C10: 900 | D10: 900 | E10: 900 | F10: 900 | G10: 900 | H10: 900 | I10: 900 | J10: 900 | K10: 900 | L10: 900 | M10: 900
A11: Electricity & Net ($40/mo) | B11: =ROUND(40*Assumptions!B2,0) -> 5200 | C11: =ROUND(40*Assumptions!B2,0) -> 5200 | D11: =ROUND(40*Assumptions!B2,0) -> 5200 | E11: =ROUND(40*Assumptions!B2,0) -> 5200 | F11: =ROUND(40*Assumptions!B2,0) -> 5200 | G11: =ROUND(40*Assumptions!B2,0) -> 5200 | H11: =ROUND(40*Assumptions!B2,0) -> 5200 | I11: =ROUND(40*Assumptions!B2,0) -> 5200 | J11: =ROUND(40*Assumptions!B2,0) -> 5200 | K11: =ROUND(40*Assumptions!B2,0) -> 5200 | L11: =ROUND(40*Assumptions!B2,0) -> 5200 | M11: =ROUND(40*Assumptions!B2,0) -> 5200
A12: API Requests (variable) | B12: =ROUND((Assumptions!B23/1000)*Assumptions!B22*Assumptions!B2,0) -> 3250 | C12: =ROUND((Assumptions!B23/1000)*Assumptions!B22*Assumptions!B2,0) -> 3250 | D12: =ROUND((Assumptions!B23/1000)*Assumptions!B22*Assumptions!B2,0) -> 3250 | E12: =ROUND((Assumptions!B23/1000)*Assumptions!B22*Assumptions!B2,0) -> 3250 | F12: =ROUND((Assumptions!B23/1000)*Assumptions!B22*Assumptions!B2,0) -> 3250 | G12: =ROUND((Assumptions!B23/1000)*Assumptions!B22*Assumptions!B2,0) -> 3250 | H12: - | I12: - | J12: - | K12: - | L12: - | M12: -
A13: Model Cloud Hosting Costs | B13: - | C13: - | D13: - | E13: - | F13: - | G13: - | H13: =ROUND(Assumptions!B85,0) -> 0 | I13: =ROUND(Assumptions!B85,0) -> 0 | J13: =ROUND(Assumptions!B85,0) -> 0 | K13: =ROUND(Assumptions!B85,0) -> 0 | L13: =ROUND(Assumptions!B85,0) -> 0 | M13: =ROUND(Assumptions!B85,0) -> 0
A14: Founder 1 Salary | B14: =Assumptions!B29 -> 0 | C14: =Assumptions!B29 -> 0 | D14: =Assumptions!B29 -> 0 | E14: =Assumptions!B29 -> 0 | F14: =Assumptions!B29 -> 0 | G14: =Assumptions!B29 -> 0 | H14: =Assumptions!B29 -> 0 | I14: =Assumptions!B29 -> 0 | J14: =Assumptions!B29 -> 0 | K14: =Assumptions!B29 -> 0 | L14: =Assumptions!B29 -> 0 | M14: =Assumptions!B29 -> 0
A15: Founder 2 Salary | B15: =Assumptions!B30 -> 0 | C15: =Assumptions!B30 -> 0 | D15: =Assumptions!B30 -> 0 | E15: =Assumptions!B30 -> 0 | F15: =Assumptions!B30 -> 0 | G15: =Assumptions!B30 -> 0 | H15: =Assumptions!B30 -> 0 | I15: =Assumptions!B30 -> 0 | J15: =Assumptions!B30 -> 0 | K15: =Assumptions!B30 -> 0 | L15: =Assumptions!B30 -> 0 | M15: =Assumptions!B30 -> 0
A16: TOTAL MONTHLY SPEND | B16: =SUM(B3:B15) -> 513080 | C16: =SUM(C3:C15) -> 40850 | D16: =SUM(D3:D15) -> 15850 | E16: =SUM(E3:E15) -> 15850 | F16: =SUM(F3:F15) -> 15850 | G16: =SUM(G3:G15) -> 15850 | H16: =SUM(H3:H15) -> 12600 | I16: =SUM(I3:I15) -> 12600 | ... M16: =SUM(M3:M15) -> 12600
A17: CUMULATIVE SPEND | B17: =B16 -> 513080 | C17: =B17+C16 -> 553930 | D17: =C17+D16 -> 569780 | E17: =D17+E16 -> 585630 | F17: =E17+F16 -> 601480 | G17: =F17+G16 -> 617330 | H17: =G17+H16 -> 629930 | I17: =H17+I16 -> 642530 | J17: =I17+J16 -> 655130 | ... M17: =L17+M16 -> 692930
A18: ← Phase 1: API (Months 1-6) | I18: ← Phase 2: Own Model (Months 7-12)

Sheet AI Model Roadmap
A1: WAKASA LABS — AI MODEL ROADMAP & ECONOMICS
A3: PHASE 1: MVP (Months 1-6) — Claude Primary, Gemini Fallback
A4: Job | B4: Model | C4: Mode | D4: Cost/Paper (Ksh) | E4: Notes
A5: Handwriting OCR | B5: Google Cloud Vision | C5: API (per call) | D5: ~0.50 | E5: Best handwriting accuracy. Keep as primary OCR
A6: Structure Extraction | B6: DeepSeek-OCR 2 | C6: Self-hosted (free) | D6: ~0.00 | E6: MIT license. Runs locally. Question segmentation
A7: AI Marking (primary) | B7: Claude Sonnet 4.6 | C7: Batch API (opt-in) | D7: ~4.42 | E7: Batch = 50% off. Only fires on AI-assist requests
A8: AI Marking (fallback) | B8: Gemini 3 Flash | C8: Batch API (auto) | D8: ~0.55 | E8: 20% of requests routed to Gemini. Redundancy
A9: MCQ Grading | B9: Local (server-side) | C9: Zero cost | D9: 0.00 | E9: Pure deterministic match. No API cost
A10: Local Keyword Grading | B10: Local (server-side) | C10: Zero cost | D10: 0.00 | E10: Cosine similarity on TF-IDF. No API cost
A12: PHASE 2: GROWTH (Months 7-18) — Data Collection & Fine-Tuning
A13: Training Data Collection Strategy | B13: Source | C13: Est. Pairs / 6 months | D13: Use For
A14: OCR corrections by lecturers | B14: Platform usage | C14: 5,000+ | D14: DeepSeek-OCR 2 fine-tune
A15: Graded answers (question + score + feedback) | B15: Platform usage | C15: 20,000+ | D15: Llama 4 Scout fine-tune (QLoRA via Unsloth on H100)
A16: Scan regions mapped to questions | B16: Platform usage | C16: 10,000+ | D16: Qwen 2.5-VL segmentation fine-tune
A18: PHASE 3: SCALE (Year 2+) — Acsis Model Deployed
A19: Model | B19: Job | C19: Base Model | D19: Fine-Tune Cost (Ksh) | E19: Hosting Cost/mo (Ksh) | F19: GPU allocation
A20: Acsis-OCR (DeepSeek-OCR 2) | B20: Structure extraction + printed text | C20: deepseek-ai/DeepSeek-OCR-2 | D20: =ROUND(30*Assumptions!B2,0) -> 3900 | E20: =ROUND(Assumptions!B78*Assumptions!B79*0.5*Assumptions!B2,0) -> 18252 | F20: 50% RTX 4090
A21: Acsis-Vision (Qwen 2.5-VL 7B) | B21: Handwriting + question segmentation | C21: Qwen/Qwen2.5-VL-7B-Instruct | D21: =ROUND(80*Assumptions!B2,0) -> 10400 | E21: =ROUND(Assumptions!B78*Assumptions!B79*0.5*Assumptions!B2,0) -> 18252 | F21: 50% RTX 4090
A22: Acsis-Mark (Llama 4 Scout) | B22: Answer marking + feedback (multimodal, vision-native) | C22: meta-llama/Llama-4-Scout-17B-16E-Instruct | D22: =ROUND(120*Assumptions!B2,0) -> 15600 | E22: =ROUND(Assumptions!B76*Assumptions!B79*Assumptions!B2,0) -> 261144 | F22: 100% H100 PCIe
A23: TOTAL — Acsis Model v1 | B23: Full pipeline replacement | C23: All three combined | D23: =ROUND(170*Assumptions!B2,0) -> 22100 | E23: =E20+E21+E22 -> 297648 | F23: Full pipeline
A25: COST CROSSOVER ANALYSIS
A26: Papers/Month | B26: Claude Batch (Ksh/mo) | C26: Gemini Fallback (Ksh/mo) | D26: Total API (Ksh/mo) | E26: Own Model (Ksh/mo) | F26: Saving with Own Model
A27: 500 | B27: =ROUND(500*0.0222*130,0) -> 1443 | C27: =ROUND(500*0.0042*0.2*130,0) -> 55 | D27: =B27+C27 -> 1498 | E27: =ROUND(Assumptions!B70*Assumptions!B2,0) -> 298220 | F27: =IF(D27>E27,D27-E27,0) -> 0
A28: 1000 | B28: =ROUND(1000*0.0222*130,0) -> 2886 | C28: =ROUND(1000*0.0042*0.2*130,0) -> 109 | D28: =B28+C28 -> 2995 | E28: =ROUND(Assumptions!B70*Assumptions!B2,0) -> 298220 | F28: =IF(D28>E28,D28-E28,0) -> 0
A29: 2000 | B29: =ROUND(2000*0.0222*130,0) -> 5772 | C29: =ROUND(2000*0.0042*0.2*130,0) -> 218 | D29: =B29+C29 -> 5990 | E29: =ROUND(Assumptions!B70*Assumptions!B2,0) -> 298220 | F29: =IF(D29>E29,D29-E29,0) -> 0
A30: 3500 | B30: =ROUND(3500*0.0222*130,0) -> 10101 | C30: =ROUND(3500*0.0042*0.2*130,0) -> 382 | D30: =B30+C30 -> 10483 | E30: =ROUND(Assumptions!B70*Assumptions!B2,0) -> 298220 | F30: =IF(D30>E30,D30-E30,0) -> 0
A31: 5000 | B31: =ROUND(5000*0.0222*130,0) -> 14430 | C31: =ROUND(5000*0.0042*0.2*130,0) -> 546 | D31: =B31+C31 -> 14976 | E31: =ROUND(Assumptions!B70*Assumptions!B2,0) -> 298220 | F31: =IF(D31>E31,D31-E31,0) -> 0
A32: 10000 | B32: =ROUND(10000*0.0222*130,0) -> 28860 | C32: =ROUND(10000*0.0042*0.2*130,0) -> 1092 | D32: =B32+C32 -> 29952 | E32: =ROUND(Assumptions!B70*Assumptions!B2,0) -> 298220 | F32: =IF(D32>E32,D32-E32,0) -> 0
A33: 20000 | B33: =ROUND(20000*0.0222*130,0) -> 57720 | C33: =ROUND(20000*0.0042*0.2*130,0) -> 2184 | D33: =B33+C33 -> 59904 | E33: =ROUND(Assumptions!B70*2*Assumptions!B2,0) -> 596440 | F33: =IF(D33>E33,D33-E33,0) -> 0
A35: Note: With Scout (H100 $2.79/hr) + RTX 4090 ($0.39/hr) on RunPod, own model = ~$2,294/mo (Ksh ~298,000). Crossover vs Claude Batch API ~90,000 papers/month. Scout is a quality + independence play — justify with marking accuracy, latency, and API lock-in avoidance.

Sheet Hosting Options
A1: WAKASA LABS — GPU CLOUD HOSTING OPTIONS REFERENCE
A2: Research as at March 2026. Prices change frequently — always verify before committing.
A3: Platform | B3: Best For | C3: RTX 4090 $/hr | D3: A100 80GB $/hr | E3: Spot/Marketplace? | F3: URL
A4: RunPod (Secure Cloud) | B4: Production inference — reliable uptime, templates, one-click deploy | C4: $0.39 | D4: $1.50 | E4: No (on-demand) Community = spot ~50% off | F4: https://runpod.io/pricing
A5: Vast.ai | B5: Budget / research — cheapest raw prices via P2P marketplace | C5: ~$0.20 | D5: ~$0.67 | E5: Yes — marketplace ⚠ Uptime not guaranteed | F5: https://vast.ai
A6: Lambda Labs | B6: Research teams — no egress fees, good A100/H100 availability | C6: ~$0.50 | D6: $1.10 | E6: No (reserved/on-demand) | F6: https://lambdalabs.com/service/gpu-cloud
A7: Together AI | B7: Serverless inference API — pay per token, no GPU management | C7: N/A | D7: N/A | E7: Per-token billing | F7: https://together.ai/pricing
A8: Modal | B8: Serverless GPU functions — sub-second cold starts, auto-scale | C8: ~$0.45 | D8: ~$1.60 | E8: Serverless / per-second | F8: https://modal.com/pricing
A9: Hugging Face Endpoints | B9: Simplest deployment — 1-click from HF model hub | C9: ~$0.60 | D9: ~$2.00 | E9: No (dedicated endpoints) | F9: https://huggingface.co/pricing#endpoints
A10: Google Cloud (GCP) | B10: Enterprise / compliance — GCP ecosystem, high SLA | C10: ~$1.20 | D10: ~$3.20 | E10: Spot available (~60% off) | F10: https://cloud.google.com/compute/gpus-pricing
A12: ★ OUR RECOMMENDATION
A13: For Wakasa Labs Phase 2 (own model, production serving): RunPod Secure Cloud on-demand gives the best balance of reliability and price. Use Vast.ai for fine-tuning runs only (cheaper spot, interruptions acceptable). Graduate to Together AI or Modal serverless once volume justifies per-token billing.
A15: COLOUR CODE LEGEND — all sheets
A16: Blue text | B16: Hardcoded input — you can/should change this
A17: Black text | B17: Formula — calculated automatically
A18: Dark green text | B18: Cross-sheet reference — links to another tab
A19: Yellow background | B19: Key assumption — review before presenting to investor
A20: Navy header | B20: Section header
A21: Light blue header | B21: Column header
A22: Pale blue row | B22: Total / subtotal row
